Workbook

Sheet SOBRANTE CTA 279510020
A1: SUC | B1: CAJERO | C1: VALOR SOBRANTE | D1: VALOR CANCELADO | E1: NUEVO VALOR | F1: FECHA GRABADO dd/mm/aaaa | G1: FECHA SIN FORMULA. DÍA DEL ARQUEO | H1: CAJERO | I1: TIPO DE DIFERENCIA: CONTABLE / FISÍCA | J1: NOMBRE CAJERO
A2: 7 | B2: 5613 | C2: 100000 | D2: 100000 | E2: =+C2-D2 -> 0 | F2: 45965 | G2: 20251103 | H2: =VLOOKUP(B2,CAJEROS!B:D,3,0) -> Dispensador | I2: Cuadre diario | J2: =VLOOKUP(B2,CAJEROS!B:E,4,0) -> SUC_MOLIN2
A3: 60 | B3: 8719 | C3: 300000 | E3: =+C3-D3 -> 300000 | F3: 45965 | G3: 20251103 | H3: =VLOOKUP(B3,CAJEROS!B:D,3,0) -> Dispensador | I3: Cuadre diario | J3: =VLOOKUP(B3,CAJEROS!B:E,4,0) -> HALLCALIPR1
A4: 60 | B4: 8721 | C4: 200000 | E4: =+C4-D4 -> 200000 | F4: 45965 | G4: 20251103 | H4: =VLOOKUP(B4,CAJEROS!B:D,3,0) -> Dispensador | I4: Cuadre diario | J4: =VLOOKUP(B4,CAJEROS!B:E,4,0) -> HALLCALIPR3
A5: 60 | B5: 8725 | C5: 200000 | E5: =+C5-D5 -> 200000 | F5: 45965 | G5: 20251103 | H5: =VLOOKUP(B5,CAJEROS!B:D,3,0) -> Dispensador | I5: Cuadre diario | J5: =VLOOKUP(B5,CAJEROS!B:E,4,0) -> HALLCALIPR7
A6: 78 | B6: 8593 | C6: 100000 | E6: =+C6-D6 -> 100000 | F6: 45965 | G6: 20251103 | H6: =VLOOKUP(B6,CAJEROS!B:D,3,0) -> Dispensador | I6: Cuadre diario | J6: =VLOOKUP(B6,CAJEROS!B:E,4,0) -> HALLCACIQ4
A7: 101 | B7: 4867 | C7: 50000 | E7: =+C7-D7 -> 50000 | F7: 45965 | G7: 20251103 | H7: =VLOOKUP(B7,CAJEROS!B:D,3,0) -> Dispensador | I7: Cuadre diario | J7: =VLOOKUP(B7,CAJEROS!B:E,4,0) -> SUC_MDRIVE3
A8: 153 | B8: 9881 | C8: 1010000 | D8: 910000 | E8: =+C8-D8 -> 100000 | F8: 45965 | G8: 20251103 | H8: =VLOOKUP(B8,CAJEROS!B:D,3,0) -> Dispensador | I8: Cuadre diario | J8: =VLOOKUP(B8,CAJEROS!B:E,4,0) -> EXITOIBAG_3
A9: 186 | B9: 6509 | C9: 450000 | D9: 260000 | E9: =+C9-D9 -> 190000 | F9: 45965 | G9: 20251103 | H9: =VLOOKUP(B9,CAJEROS!B:D,3,0) -> Dispensador | I9: Cuadre diario | J9: =VLOOKUP(B9,CAJEROS!B:E,4,0) -> SUC_GALERI2
A10: 186 | B10: 6513 | C10: 310000 | E10: =+C10-D10 -> 310000 | F10: 45965 | G10: 20251103 | H10: =VLOOKUP(B10,CAJEROS!B:D,3,0) -> Dispensador | I10: Cuadre diario | J10: =VLOOKUP(B10,CAJEROS!B:E,4,0) -> SUC_GALERI4
A11: 186 | B11: 6514 | C11: 390000 | E11: =+C11-D11 -> 390000 | F11: 45965 | G11: 20251103 | H11: =VLOOKUP(B11,CAJEROS!B:D,3,0) -> Dispensador | I11: Cuadre diario | J11: =VLOOKUP(B11,CAJEROS!B:E,4,0) -> SUC_GALERI5
A12: 225 | B12: 8866 | C12: 190000 | E12: =+C12-D12 -> 190000 | F12: 45965 | G12: 20251103 | H12: =VLOOKUP(B12,CAJEROS!B:D,3,0) -> Dispensador | I12: Cuadre diario | J12: =VLOOKUP(B12,CAJEROS!B:E,4,0) -> SMALPLANQS4
A13: 229 | B13: 8957 | C13: 120000 | E13: =+C13-D13 -> 120000 | F13: 45965 | G13: 20251103 | H13: =VLOOKUP(B13,CAJEROS!B:D,3,0) -> Dispensador | I13: Cuadre diario | J13: =VLOOKUP(B13,CAJEROS!B:E,4,0) -> SUCPASERIO3
A14: 240 | B14: 4510 | C14: 150000 | E14: =+C14-D14 -> 150000 | F14: 45965 | G14: 20251103 | H14: =VLOOKUP(B14,CAJEROS!B:D,3,0) -> Dispensador | I14: Cuadre diario | J14: =VLOOKUP(B14,CAJEROS!B:E,4,0) -> SUC_SANTFE1
A15: 240 | B15: 6372 | C15: 100000 | E15: =+C15-D15 -> 100000 | F15: 45965 | G15: 20251103 | H15: =VLOOKUP(B15,CAJEROS!B:D,3,0) -> Dispensador | I15: Cuadre diario | J15: =VLOOKUP(B15,CAJEROS!B:E,4,0) -> STAFEANTI_2
A16: 289 | B16: 4593 | C16: 1900000 | D16: 1230000 | E16: =+C16-D16 -> 670000 | F16: 45965 | G16: 20251103 | H16: =VLOOKUP(B16,CAJEROS!B:D,3,0) -> Dispensador | I16: Cuadre diario | J16: =VLOOKUP(B16,CAJEROS!B:E,4,0) -> SUC_PGAIT3
A17: 289 | B17: 8225 | C17: 580000 | D17: =300000+240000 -> 540000 | E17: =+C17-D17 -> 40000 | F17: 45965 | G17: 20251103 | H17: =VLOOKUP(B17,CAJEROS!B:D,3,0) -> Dispensador | I17: Cuadre diario | J17: =VLOOKUP(B17,CAJEROS!B:E,4,0) -> PUERTO_GAI4
A18: 291 | B18: 4410 | C18: 5440000 | D18: 5200000 | E18: =+C18-D18 -> 240000 | F18: 45965 | G18: 20251103 | H18: =VLOOKUP(B18,CAJEROS!B:D,3,0) -> Dispensador | I18: Cuadre diario | J18: =VLOOKUP(B18,CAJEROS!B:E,4,0) -> SUC_PALMAS2
A19: 317 | B19: 9730 | C19: 30000 | E19: =+C19-D19 -> 30000 | F19: 45965 | G19: 20251103 | H19: =VLOOKUP(B19,CAJEROS!B:D,3,0) -> Dispensador | I19: Cuadre diario | J19: =VLOOKUP(B19,CAJEROS!B:E,4,0) -> SUCARAUCA_5
A20: 322 | B20: 2441 | C20: 1210000 | D20: 1200000 | E20: =+C20-D20 -> 10000 | F20: 45965 | G20: 20251103 | H20: =VLOOKUP(B20,CAJEROS!B:D,3,0) -> Dispensador | I20: Cuadre diario | J20: =VLOOKUP(B20,CAJEROS!B:E,4,0) -> SUCSANGIL1
A21: 372 | B21: 7917 | C21: 40000 | D21: 30000 | E21: =+C21-D21 -> 10000 | F21: 45965 | G21: 20251103 | H21: =VLOOKUP(B21,CAJEROS!B:D,3,0) -> Dispensador | I21: Cuadre diario | J21: =VLOOKUP(B21,CAJEROS!B:E,4,0) -> SUCFACATA_3
A22: 376 | B22: 2854 | C22: 200000 | D22: 190000 | E22: =+C22-D22 -> 10000 | F22: 45965 | G22: 20251103 | H22: =VLOOKUP(B22,CAJEROS!B:D,3,0) -> Dispensador | I22: Cuadre diario | J22: =VLOOKUP(B22,CAJEROS!B:E,4,0) -> _FREDONIA_
A23: 389 | B23: 4689 | C23: 550000 | E23: =+C23-D23 -> 550000 | F23: 45965 | G23: 20251103 | H23: =VLOOKUP(B23,CAJEROS!B:D,3,0) -> Dispensador | I23: Cuadre diario | J23: =VLOOKUP(B23,CAJEROS!B:E,4,0) -> SUC_MARIQ3
A24: 389 | B24: 4690 | C24: 1030000 | E24: =+C24-D24 -> 1030000 | F24: 45965 | G24: 20251103 | H24: =VLOOKUP(B24,CAJEROS!B:D,3,0) -> Dispensador | I24: Cuadre diario | J24: =VLOOKUP(B24,CAJEROS!B:E,4,0) -> SUC_MARIQ4
A25: 398 | B25: 9562 | C25: 1240000 | D25: 1240000 | E25: =+C25-D25 -> 0 | F25: 45965 | G25: 20251103 | H25: =VLOOKUP(B25,CAJEROS!B:D,3,0) -> Dispensador | I25: Cuadre diario | J25: =VLOOKUP(B25,CAJEROS!B:E,4,0) -> SUC_CHINU2
A26: 404 | B26: 5873 | C26: 320000 | E26: =+C26-D26 -> 320000 | F26: 45965 | G26: 20251103 | H26: =VLOOKUP(B26,CAJEROS!B:D,3,0) -> Dispensador | I26: Cuadre diario | J26: =VLOOKUP(B26,CAJEROS!B:E,4,0) -> JARDIN_2
A27: 422 | B27: 4221 | C27: 150000 | E27: =+C27-D27 -> 150000 | F27: 45965 | G27: 20251103 | H27: =VLOOKUP(B27,CAJEROS!B:D,3,0) -> Dispensador | I27: Cuadre diario | J27: =VLOOKUP(B27,CAJEROS!B:E,4,0) -> CHAPARRAL
A28: 451 | B28: 4967 | C28: 240000 | E28: =+C28-D28 -> 240000 | F28: 45965 | G28: 20251103 | H28: =VLOOKUP(B28,CAJEROS!B:D,3,0) -> Dispensador | I28: Cuadre diario | J28: =VLOOKUP(B28,CAJEROS!B:E,4,0) -> SUCPTOASIS2
A29: 484 | B29: 3268 | C29: 200000 | E29: =+C29-D29 -> 200000 | F29: 45965 | G29: 20251103 | H29: =VLOOKUP(B29,CAJEROS!B:D,3,0) -> Dispensador | I29: Cuadre diario | J29: =VLOOKUP(B29,CAJEROS!B:E,4,0) -> MAGANGUE_3
A30: 492 | B30: 6238 | C30: 100000 | D30: 80000 | E30: =+C30-D30 -> 20000 | F30: 45965 | G30: 20251103 | H30: =VLOOKUP(B30,CAJEROS!B:D,3,0) -> Dispensador | I30: Cuadre diario | J30: =VLOOKUP(B30,CAJEROS!B:E,4,0) -> SUCGARAGOA
A31: 499 | B31: 9808 | C31: 1600000 | E31: =+C31-D31 -> 1600000 | F31: 45965 | G31: 20251103 | H31: =VLOOKUP(B31,CAJEROS!B:D,3,0) -> Dispensador | I31: Cuadre diario | J31: =VLOOKUP(B31,CAJEROS!B:E,4,0) -> SUCPARFAB10
A32: 502 | B32: 4626 | C32: 290000 | D32: 240000 | E32: =+C32-D32 -> 50000 | F32: 45965 | G32: 20251103 | H32: =VLOOKUP(B32,CAJEROS!B:D,3,0) -> Dispensador | I32: Cuadre diario | J32: =VLOOKUP(B32,CAJEROS!B:E,4,0) -> SUC_LEYVA2
A33: 503 | B33: 5032 | C33: 100000 | E33: =+C33-D33 -> 100000 | F33: 45965 | G33: 20251103 | H33: =VLOOKUP(B33,CAJEROS!B:D,3,0) -> Dispensador | I33: Cuadre diario | J33: =VLOOKUP(B33,CAJEROS!B:E,4,0) -> YARUMAL2
A34: 522 | B34: 4590 | C34: 1120000 | D34: 1100000 | E34: =+C34-D34 -> 20000 | F34: 45965 | G34: 20251103 | H34: =VLOOKUP(B34,CAJEROS!B:D,3,0) -> Dispensador | I34: Cuadre diario | J34: =VLOOKUP(B34,CAJEROS!B:E,4,0) -> SUC_PUERTC1
A35: 523 | B35: 3997 | C35: 280000 | E35: =+C35-D35 -> 280000 | F35: 45965 | G35: 20251103 | H35: =VLOOKUP(B35,CAJEROS!B:D,3,0) -> Dispensador | I35: Cuadre diario | J35: =VLOOKUP(B35,CAJEROS!B:E,4,0) -> SUC_OVALLE3
A36: 536 | B36: 8993 | C36: 290000 | E36: =+C36-D36 -> 290000 | F36: 45965 | G36: 20251103 | H36: =VLOOKUP(B36,CAJEROS!B:D,3,0) -> Dispensador | I36: Cuadre diario | J36: =VLOOKUP(B36,CAJEROS!B:E,4,0) -> SUC_QUIBDO8
A37: 555 | B37: 7265 | C37: 1340000 | D37: 700000 | E37: =+C37-D37 -> 640000 | F37: 45965 | G37: 20251103 | H37: =VLOOKUP(B37,CAJEROS!B:D,3,0) -> Dispensador | I37: Cuadre diario | J37: =VLOOKUP(B37,CAJEROS!B:E,4,0) -> SUC_BARSAN1
A38: 584 | B38: 3068 | C38: 100000 | E38: =+C38-D38 -> 100000 | F38: 45965 | G38: 20251103 | H38: =VLOOKUP(B38,CAJEROS!B:D,3,0) -> Dispensador | I38: Cuadre diario | J38: =VLOOKUP(B38,CAJEROS!B:E,4,0) -> HALLCHIGOR3
A39: 584 | B39: 6874 | C39: 200000 | E39: =+C39-D39 -> 200000 | F39: 45965 | G39: 20251103 | H39: =VLOOKUP(B39,CAJEROS!B:D,3,0) -> Dispensador | I39: Cuadre diario | J39: =VLOOKUP(B39,CAJEROS!B:E,4,0) -> HALLCHIGOR2
A40: 631 | B40: 2617 | C40: 50000 | E40: =+C40-D40 -> 50000 | F40: 45965 | G40: 20251103 | H40: =VLOOKUP(B40,CAJEROS!B:D,3,0) -> Dispensador | I40: Cuadre diario | J40: =VLOOKUP(B40,CAJEROS!B:E,4,0) -> SUCURIBIA_3
...

Sheet HISTORICO 279510020
A1: SUC | B1: CODIGO | C1: VALOR SOBRANTE | D1: VALOR CANCELADO | E1: NUEVO VALOR | F1: FECHA GRABADO formato dd/mm/aaaa | G1: FECHA SIN FORMULA. DÍA DEL ARQUEO | H1: CAJERO | I1: OBSERVACIONES | J1: OBSERVACIONES
A2: 61 | B2: 788 | C2: 1370000 | D2: 1370000 | E2: 0 | F2: 45870 | G2: 20250731 | H2: Multifuncional | I2: Cuadre diario | J2: MFSUCLAEST1
A3: 322 | B3: 2444 | C3: 920000 | D3: 920000 | E3: =+C3-D3 -> 0 | F3: 45870 | G3: 20250731 | H3: =VLOOKUP(B3,CAJEROS!B:D,3,0) -> Multifuncional | I3: Cuadre diario | J3: =VLOOKUP(B3,CAJEROS!B:E,4,0) -> MFSUCSNGIL1
A4: 6 | B4: 5001 | C4: 190000 | D4: 190000 | E4: =+C4-D4 -> 0 | F4: 45870 | G4: 20250731 | H4: =VLOOKUP(B4,CAJEROS!B:D,3,0) -> Multifuncional | I4: Cuadre diario | J4: =VLOOKUP(B4,CAJEROS!B:E,4,0) -> MF_AVJUNIN
A5: 361 | B5: 5005 | C5: 1550000 | D5: 1550000 | E5: =+C5-D5 -> 0 | F5: 45870 | G5: 20250731 | H5: =VLOOKUP(B5,CAJEROS!B:D,3,0) -> Multifuncional | I5: Cuadre diario | J5: =VLOOKUP(B5,CAJEROS!B:E,4,0) -> MF_CDPFONTI
A6: 623 | B6: 5047 | C6: 1480000 | D6: 1480000 | E6: 0 | F6: 45870 | G6: 20250731 | H6: Multifuncional | I6: Cuadre diario | J6: MF_FMANIZAL
A7: 262 | B7: 5153 | C7: 2210000 | D7: 2210000 | E7: =+C7-D7 -> 0 | F7: 45870 | G7: 20250731 | H7: =VLOOKUP(B7,CAJEROS!B:D,3,0) -> Multifuncional | I7: Cuadre diario | J7: =VLOOKUP(B7,CAJEROS!B:E,4,0) -> MF_DUITAMA
A8: 217 | B8: 5208 | C8: 100000 | D8: 100000 | E8: =+C8-D8 -> 0 | F8: 45870 | G8: 20250731 | H8: =VLOOKUP(B8,CAJEROS!B:D,3,0) -> Multifuncional | I8: Cuadre diario | J8: =VLOOKUP(B8,CAJEROS!B:E,4,0) -> MF_MONTEVID
A9: 79 | B9: 6245 | C9: 220000 | D9: 220000 | E9: =+C9-D9 -> 0 | F9: 45870 | G9: 20250731 | H9: =VLOOKUP(B9,CAJEROS!B:D,3,0) -> Multifuncional | I9: Cuadre diario | J9: =VLOOKUP(B9,CAJEROS!B:E,4,0) -> MF_LAQUINTA
A10: 348 | B10: 6724 | C10: 2913000 | D10: 2913000 | E10: =+C10-D10 -> 0 | F10: 45870 | G10: 20250731 | H10: =VLOOKUP(B10,CAJEROS!B:D,3,0) -> Multifuncional | I10: Cuadre diario | J10: =VLOOKUP(B10,CAJEROS!B:E,4,0) -> MF_SANANDRE
A11: 166 | B11: 7939 | C11: 60000 | D11: 60000 | E11: =+C11-D11 -> 0 | F11: 45870 | G11: 20250731 | H11: =VLOOKUP(B11,CAJEROS!B:D,3,0) -> Multifuncional | I11: Cuadre diario | J11: =VLOOKUP(B11,CAJEROS!B:E,4,0) -> MF_ALDELSI1
A12: 569 | B12: 8129 | C12: 1843000 | D12: 1843000 | E12: =+C12-D12 -> 0 | F12: 45870 | G12: 20250731 | H12: =VLOOKUP(B12,CAJEROS!B:D,3,0) -> Multifuncional | I12: Cuadre diario | J12: =VLOOKUP(B12,CAJEROS!B:E,4,0) -> MF_BUENMON2
A13: 915 | B13: 8313 | C13: 1060000 | D13: 1060000 | E13: 0 | F13: 45870 | G13: 20250731 | H13: Multifuncional | I13: Cuadre diario | J13: MF_BANLABB1
A14: 302 | B14: 5170 | C14: 580000 | D14: 580000 | E14: 0 | F14: 45870 | G14: 20250731 | H14: Multifuncional | I14: Cuadre diario | J14: MF_QUEBRASE
A15: 93 | B15: 7126 | C15: 1411000 | D15: 1411000 | E15: 0 | F15: 45870 | G15: 20250731 | H15: Multifuncional | I15: Cuadre diario | J15: MF_SAHAGUN
A16: 32 | B16: 5027 | C16: 220000 | D16: 220000 | E16: =+C16-D16 -> 0 | F16: 45870 | G16: 20250731 | H16: =VLOOKUP(B16,CAJEROS!B:D,3,0) -> Multifuncional | I16: Cuadre diario | J16: =VLOOKUP(B16,CAJEROS!B:E,4,0) -> MF_ANTCOUNT
A17: 76 | B17: 5126 | C17: 100000 | D17: 100000 | E17: =+C17-D17 -> 0 | F17: 45870 | G17: 20250731 | H17: =VLOOKUP(B17,CAJEROS!B:D,3,0) -> Multifuncional | I17: Cuadre diario | J17: =VLOOKUP(B17,CAJEROS!B:E,4,0) -> MF_NEIVA
A18: 60 | B18: 8719 | C18: 10000000 | D18: 10000000 | E18: 0 | F18: 45870 | G18: 20250731 | H18: Dispensador | I18: Cuadre diario | J18: HALLCALIPR1
A19: 335 | B19: 5741 | C19: 700000 | D19: 700000 | E19: 0 | F19: 45870 | G19: 20250731 | H19: Dispensador | I19: Cuadre diario | J19: SUC_CAJICA5
A20: 1 | B20: 5000 | C20: 50000 | D20: 50000 | E20: =+C20-D20 -> 0 | F20: 45873 | G20: 20250803 | H20: =VLOOKUP(B20,CAJEROS!B:D,3,0) -> Multifuncional | I20: Cuadre diario | J20: =VLOOKUP(B20,CAJEROS!B:E,4,0) -> MF_CARABOBO
A21: 852 | B21: 5050 | C21: 2510000 | D21: 2510000 | E21: =+C21-D21 -> 0 | F21: 45873 | G21: 20250803 | H21: =VLOOKUP(B21,CAJEROS!B:D,3,0) -> Multifuncional | I21: Cuadre diario | J21: =VLOOKUP(B21,CAJEROS!B:E,4,0) -> MF_VICPLAZA
A22: 250 | B22: 5197 | C22: 650000 | D22: 650000 | E22: =+C22-D22 -> 0 | F22: 45873 | G22: 20250803 | H22: =VLOOKUP(B22,CAJEROS!B:D,3,0) -> Multifuncional | I22: Cuadre diario | J22: =VLOOKUP(B22,CAJEROS!B:E,4,0) -> MF_MODELIA
A23: 769 | B23: 8679 | C23: 1580000 | D23: 1580000 | E23: =+C23-D23 -> 0 | F23: 45873 | G23: 20250803 | H23: =VLOOKUP(B23,CAJEROS!B:D,3,0) -> Multifuncional | I23: Cuadre diario | J23: =VLOOKUP(B23,CAJEROS!B:E,4,0) -> MF_SUCPPRA1
A24: 64 | B24: 6447 | C24: 510000 | D24: 510000 | E24: 0 | F24: 45870 | G24: 20250731 | H24: Dispensador | I24: Cuadre diario | J24: VIPASA_5_R
A25: 849 | B25: 9723 | C25: 40000 | D25: 40000 | E25: 0 | F25: 45870 | G25: 20250731 | H25: Dispensador | I25: Cuadre diario | J25: SUCUNIVILL4
A26: 866 | B26: 6260 | C26: 100000 | D26: 100000 | E26: 0 | F26: 45870 | G26: 20250731 | H26: Dispensador | I26: Cuadre diario | J26: SUC_FLORID4
A27: 305 | B27: 4897 | C27: 200000 | D27: 200000 | E27: 0 | F27: 45873 | G27: 20250803 | H27: Dispensador | I27: Cuadre diario | J27: SUC_VILLAN3
A28: 536 | B28: 4795 | C28: 1030000 | D28: 1030000 | E28: 0 | F28: 45873 | G28: 20250803 | H28: Dispensador | I28: Cuadre diario | J28: SUC_QUIBDO1
A29: 927 | B29: 5749 | C29: 70000 | D29: 70000 | E29: 0 | F29: 45873 | G29: 20250803 | H29: Dispensador | I29: Cuadre diario | J29: SUC_MOCOA1
A30: 927 | B30: 5750 | C30: 30000 | D30: 30000 | E30: 0 | F30: 45873 | G30: 20250803 | H30: Dispensador | I30: Cuadre diario | J30: SUC_MOCOA2
A31: 966 | B31: 9943 | C31: 200000 | D31: 200000 | E31: 0 | F31: 45873 | G31: 20250803 | H31: Dispensador | I31: Cuadre diario | J31: HALLSUCMTE3
A32: 331 | B32: 574 | C32: 280000 | D32: 280000 | E32: =+C32-D32 -> 0 | F32: 45874 | G32: 20250804 | H32: =VLOOKUP(B32,CAJEROS!B:D,3,0) -> Multifuncional | I32: Cuadre diario | J32: =VLOOKUP(B32,CAJEROS!B:E,4,0) -> MF_SUCARKA1
A33: 61 | B33: 788 | C33: 1675000 | D33: 1675000 | E33: =+C33-D33 -> 0 | F33: 45874 | G33: 20250804 | H33: =VLOOKUP(B33,CAJEROS!B:D,3,0) -> Multifuncional | I33: Cuadre diario | J33: =VLOOKUP(B33,CAJEROS!B:E,4,0) -> MFSUCLAEST1
A34: 6 | B34: 5001 | C34: 90000 | D34: 90000 | E34: =+C34-D34 -> 0 | F34: 45874 | G34: 20250804 | H34: =VLOOKUP(B34,CAJEROS!B:D,3,0) -> Multifuncional | I34: Cuadre diario | J34: =VLOOKUP(B34,CAJEROS!B:E,4,0) -> MF_AVJUNIN
A35: 517 | B35: 5053 | C35: 1684000 | D35: 1684000 | E35: =+C35-D35 -> 0 | F35: 45874 | G35: 20250804 | H35: =VLOOKUP(B35,CAJEROS!B:D,3,0) -> Multifuncional | I35: Cuadre diario | J35: =VLOOKUP(B35,CAJEROS!B:E,4,0) -> MF_RODADERO
A36: 781 | B36: 5057 | C36: 2970000 | D36: 2970000 | E36: =+C36-D36 -> 0 | F36: 45874 | G36: 20250804 | H36: =VLOOKUP(B36,CAJEROS!B:D,3,0) -> Multifuncional | I36: Cuadre diario | J36: =VLOOKUP(B36,CAJEROS!B:E,4,0) -> MF_PRPLAZA
A37: 383 | B37: 5194 | C37: 1980000 | D37: 1980000 | E37: =+C37-D37 -> 0 | F37: 45874 | G37: 20250804 | H37: =VLOOKUP(B37,CAJEROS!B:D,3,0) -> Multifuncional | I37: Cuadre diario | J37: =VLOOKUP(B37,CAJEROS!B:E,4,0) -> MF_MADRID
A38: 859 | B38: 5207 | C38: 1762000 | D38: 1762000 | E38: =+C38-D38 -> 0 | F38: 45874 | G38: 20250804 | H38: =VLOOKUP(B38,CAJEROS!B:D,3,0) -> #N/A | I38: Cuadre diario | J38: =VLOOKUP(B38,CAJEROS!B:E,4,0) -> #N/A
A39: 941 | B39: 5220 | C39: 2840000 | D39: 2840000 | E39: =+C39-D39 -> 0 | F39: 45874 | G39: 20250804 | H39: =VLOOKUP(B39,CAJEROS!B:D,3,0) -> Multifuncional | I39: Cuadre diario | J39: =VLOOKUP(B39,CAJEROS!B:E,4,0) -> MF_NEIVANVA
A40: 236 | B40: 8497 | C40: 100000 | D40: 100000 | E40: =+C40-D40 -> 0 | F40: 45874 | G40: 20250804 | H40: =VLOOKUP(B40,CAJEROS!B:D,3,0) -> Multifuncional | I40: Cuadre diario | J40: =VLOOKUP(B40,CAJEROS!B:E,4,0) -> MF_EXITCOL2
...

Sheet CAJEROS
A1: SUC | B1: Cajero | C1: Marca | D1: Cajero | E1: NOMBRE DEL CAJERO
A2: 1 | B2: 4959 | C2: NCR | D2: Dispensador | E2: SUC_CARABO2
A3: 1 | B3: 5000 | C3: BELLTECH | D3: Multifuncional | E3: MF_CARABOBO
A4: 4 | B4: 316 | C4: BELLTECH | D4: Multifuncional | E4: MF_SUCLAUR3
A5: 4 | B5: 8626 | C5: NCR | D5: Dispensador | E5: SUCLAURELE1
A6: 4 | B6: 8627 | C6: NCR | D6: Dispensador | E6: SUCLAURELE2
A7: 4 | B7: 8628 | C7: NCR | D7: Dispensador | E7: SUCLAURELE3
A8: 4 | B8: 8629 | C8: NCR | D8: Dispensador | E8: SUCLAURELE4
A9: 4 | B9: 8630 | C9: BELLTECH | D9: Multifuncional | E9: MF_SUCLAUR1
A10: 4 | B10: 8631 | C10: BELLTECH | D10: Multifuncional | E10: MF_SUCLAUR2
A11: 5 | B11: 4866 | C11: #N/A | D11: Multifuncional | E11: MFSUCAVPBL1
A12: 6 | B12: 5001 | C12: BELLTECH | D12: Multifuncional | E12: MF_AVJUNIN
A13: 7 | B13: 5059 | C13: DIEBOLD | D13: Multifuncional | E13: MF_LOSMOLI1
A14: 7 | B14: 5613 | C14: DIEBOLD | D14: Dispensador | E14: SUC_MOLIN2
A15: 7 | B15: 5614 | C15: NCR | D15: Dispensador | E15: SUC_MOLIN3
A16: 7 | B16: 5615 | C16: DIEBOLD | D16: Dispensador | E16: SUC_MOLIN4
A17: 7 | B17: 5616 | C17: DIEBOLD | D17: Dispensador | E17: SUC_MOLIN5
A18: 7 | B18: 5617 | C18: NCR | D18: Dispensador | E18: SUC_MOLIN6
A19: 7 | B19: 7812 | C19: DIEBOLD | D19: Multifuncional | E19: MF_LOSMOLI3
A20: 8 | B20: 5079 | C20: BELLTECH | D20: Multifuncional | E20: MF_LAPLAYA
A21: 8 | B21: 5655 | C21: WINCOR | D21: Dispensador | E21: SUC_LAPLAY1
A22: 8 | B22: 5656 | C22: WINCOR | D22: Dispensador | E22: SUC_LAPLAY2
A23: 8 | B23: 7272 | C23: DIEBOLD | D23: Multifuncional | E23: MF_LAPLAYA2
... A292: 291 | B292: 8188 | C292: NCR | D292: Dispensador | E292: SUCPALMAS3
A293: 292 | B293: 278 | C293: #N/A | D293: Multifuncional | E293: ATM MF SUC CTRO DE CONFECCIO2
A294: 292 | B294: 5116 | C294: BELLTECH | D294: Multifuncional | E294: MF_CONFECCI
A295: 292 | B295: 5426 | C295: WINCOR | D295: Dispensador | E295: CONFECCION5
A296: 297 | B296: 4564 | C296: NCR | D296: Dispensador | E296: SUC_AGUAC3
A297: 297 | B297: 4565 | C297: NCR | D297: Dispensador | E297: SUC_AGUAC4
A298: 297 | B298: 5398 | C298: DIEBOLD | D298: Dispensador | E298: AGUACHICA2
A299: 300 | B299: 5139 | C299: BELLTECH | D299: Multifuncional | E299: MF_AUTOP98
A300: 302 | B300: 5170 | C300: BELLTECH | D300: Multifuncional | E300: MF_QUEBRASE
A301: 305 | B301: 3278 | C301: NCR | D301: Dispensador | E301: VILLACASAN1
A302: 305 | B302: 3279 | C302: NCR | D302: Dispensador | E302: VILLACASAN2
A303: 305 | B303: 4897 | C303: DIEBOLD | D303: Dispensador | E303: SUC_VILLAN3
A304: 305 | B304: 7722 | C304: NCR | D304: Dispensador | E304: VILLACASAN4
A305: 306 | B305: 428 | C305: #N/A | D305: Multifuncional | E305: ATM MF SUC BARRANCABERMEJA 1
A306: 306 | B306: 519 | C306: #N/A | D306: Dispensador | E306: #N/A
A307: 306 | B307: 535 | C307: #N/A | D307: Dispensador | E307: #N/A
A308: 306 | B308: 539 | C308: #N/A | D308: Dispensador | E308: #N/A
...
